\begin{savequote}[45mm]
\ascii{Any fool can write code that a computer can understand. Good programmers write code that humans can understand.}
\qauthor{\ascii{- Martin Flower}}
\end{savequote}

\chapter{异常信息} 
\label{ch:except-msg}

\begin{content}

当用例失败后，\ascii{xUnit Mars}能够在终端打印如下信息，方便用户快速修复失败的用例。

\begin{nodiff}{期望的异常信息}
 \begin{c++}
assertion fail in the runTest
/home/horance/code/cpp/cut/test/hamcrest/core/ComparatorTest.cpp:12
Expected: a value eq <254: int>
     but: <255: int> eq <254: int> got false
 \end{c++}
\end{nodiff}

\end{content}

\section{字符串}

\begin{content}

\subsection{失败}

增加一个失败的测试用例，当\ascii{runTest}因断言失败而抛出\ascii{AssertionError}异常时，在\ascii{TestResult}收集异常信息。

\begin{nodiff}{test/mars/core/TestCaseSpec.cc}
 \begin{c++}
namespace {
  struct FailureOnRunningTest : TestCase {
    const char* expectMsg() const {
      return "assertion fail in the runTest\n"
              "product.cc:57\n"
              "expected value == 2, but got 3";
    }

  private:
    void runTest() override {
      throw AssertionError("product.cc:57", "expected value == 2, but got 3");
    }
  };
}

TEST_F(TestCaseSpec, assert_except_msg_on_running_test_failed) {
  FailureOnRunningTest test;
  run(test);

  auto& fails = result.getFailures();
  ASSERT_EQ(1, fails.size());
  ASSERT_EQ(test.expectMsg(), fails[0]);
}
 \end{c++}
\end{nodiff}

\subsubsection{缓存异常信息}

为了快速通过测试，对外提供\ascii{getFailures}查询接口，供外部用户获取异常信息。并在\ascii{TestResult.h}建立相应的数据结构，完成异常信息的缓存。

\begin{nodiff}{include/mars/core/TestResult.h}
 \begin{c++}
#include <string>
#include <vector>

struct TestCaseFunctor;

struct TestResult {
  TestResult();

  int failCount() const;
  int errorCount() const;

  bool protect(const TestCaseFunctor&);

  using TestFailures = std::vector<std::string>;
  const TestFailures& getFailures() const;

private:
  void addFailure(std::string&& msg);
  void addError();

private:
  int numOfFails;
  int numOfErrors;
  TestFailures failures;
};
 \end{c++}
\end{nodiff}

当异常被捕获后，通过失败监听接口\ascii{addFailure}添加至缓存\ascii{failures}。

\begin{nodiff}{src/mars/core/TestResult.cc}
 \begin{c++}
#include <mars/core/TestResult.h>
#include <mars/except/AssertionError.h>
#include <mars/core/internal/TestCaseFunctor.h>

// ...

inline void TestResult::addFailure(std::string&& msg) {
  numOfFails++;
  failures.emplace_back(std::move(msg));
}

inline void TestResult::addError() {
  numOfErrors++;
}

bool TestResult::protect(const TestCaseFunctor& f) {
  try {
    return f();
  } catch (const AssertionError& e) {
    addFailure(std::string("assertion fail") + ' ' + f.where() + '\n' + e.what());
  } catch (const std::exception&) {
    addError();
  } catch (...) {
    addError();
  }
  return false;
}

const TestFailures& TestResult::getFailures() const {
  return failures;
}
 \end{c++}
\end{nodiff}

\subsubsection{获取异常位置}

得益于\ascii{TestCaseFunctor}的可扩展性，可以方便携带额外的元数据，增加异常位置的查询接口\ascii{where}。

\begin{nodiff}{include/mars/core/internal/TestCaseFunctor.h}
 \begin{c++}
struct TestCaseFunctor {
  virtual bool operator()() const = 0;
  virtual const char* where() const = 0;
  virtual ~TestCaseFunctor() {}
};
 \end{c++}
\end{nodiff}

在\ascii{TestCase::run}实现中，通过修改\ascii{PROTECT}宏定义，并覆写\ascii{Functor::where}成员函数，报告异常发生的位置信息。

\begin{nodiff}{src/mars/core/TestResult.cc}
 \begin{c++}
namespace {
  struct Functor : TestCaseFunctor {
    using Method = void(TestCase::*)();

    Functor(TestCase* self, Method method, const char* place)
      : self(self), method(method), place(place) {
    }

  private:
    bool operator()() const override {
      (self->*method)();
      return true;
    }

    const char* where() const override {
      return place;
    }

  private:
    TestCase* self;
    Method method;
    const char* place;
  };
}

#define PROTECT(method) \
    result.protect(Functor(this, &TestCase::method, "in the "#method))

void TestCase::run(TestResult& result) {
  if (PROTECT(setUp)) {
    PROTECT(runTest);
  }
  PROTECT(tearDown);
}
 \end{c++}
\end{nodiff}

\subsubsection{获取异常详情}

在\ascii{AssertionError.h}中，新增异常详情的查询接口\ascii{what}。

\begin{nodiff}{include/mars/except/AssertionError.h}
 \begin{c++}
#include <exception>
#include <string>

struct AssertionError : std::exception {
  AssertionError(const std::string& src, const std::string& msg);
  const char* what() const noexcept;

private:
  std::string msg;
};
 \end{c++}
\end{nodiff}

在\ascii{AssertionError.cc}中，分别实现构造函数和查询接口\ascii{what}的实现逻辑。

\begin{nodiff}{src/mars/except/AssertionError.cc}
 \begin{c++}
#include <mars/except/AssertionError.h>

AssertionError::AssertionError
  ( const std::string& src, const std::string& msg)
  : msg(src + "\n" + msg) {
}

const char* AssertionError::what() const noexcept {
  return msg.c_str();
}
 \end{c++}
\end{nodiff}

至此，测试通过。

\subsection{普通错误}

新增一个测试用例，模拟在\ascii{runTest}抛出\ascii{std::exception}异常，断言异常信息是否符合预期。

\begin{nodiff}{test/mars/core/TestCaseSpec.cc}
 \begin{c++}
namespace {
  struct ErrorOnRunningTest : TestCase {
    const char* expectMsg() const {
      return "uncaught std::exception in the runTest\n"
              "std::exception";
    }

    void runTest() override {
      throw std::exception();
    }
  };
}

TEST_F(TestCaseSpec, extract_error_msgt_on_running_test_failed) {
  ErrorOnRunningTest test;
  run(test);

  auto& errors = result.getErrors();
  ASSERT_EQ(1, errors.size());
  ASSERT_EQ(test.expectMsg(), errors.front());
}
 \end{c++}
\end{nodiff}

\subsubsection{缓存错误信息}

依葫芦画瓢，\ascii{TestResult}增加查询接口\ascii{getErrors}，重构错误的监听接口\ascii{addError}，将异常信息添加至缓存\ascii{errors}之中。

\begin{nodiff}{include/mars/core/TestResult.h}
 \begin{c++}
#include <string>
#include <vector>

struct TestCaseFunctor;

struct TestResult {
  TestResult();

  int failCount() const;
  int errorCount() const;

  bool protect(const TestCaseFunctor&);

  using TestFailures = std::vector<std::string>;
  const TestFailures& getFailures() const;

  using TestErrors = std::vector<std::string>;
  const TestErrors& getErrors() const;

private:
  void addFailure(std::string&& msg);
  void addError(std::string&& msg);

private:
  int numOfRuns;
  int numOfFails;
  int numOfErrors;

  TestFailures failures;
  TestErrors errors;
};
 \end{c++}
\end{nodiff}

实现也较为简单。

\begin{nodiff}{src/mars/core/TestResult.cc}
 \begin{c++}
inline void TestResult::addFailure(std::string&& msg) {
  numOfFails++;
  failures.emplace_back(std::move(msg));
}

inline void TestResult::addError(std::string&& msg) {
  numOfErrors++;
  errors.emplace_back(std::move(msg));
}

bool TestResult::protect(const TestCaseFunctor& f) {
  try {
    return f();
  } catch (const AssertionError& e) {
    addFailure(std::string("assertion fail") + ' ' + f.where() + '\n' + e.what());
  } catch (const std::exception& e) {
    addError(std::string("uncaught std::exception") + ' ' + f.where() + '\n' + e.what());
  } catch (...) {
    addError("");
  }
  return false;
}

const TestResult::TestFailures& TestResult::getFailures() const {
  return failures;
}

const TestResult::TestErrors& TestResult::getErrors() const {
  return errors;
}
 \end{c++}
\end{nodiff}

至此，测试通过。

\subsection{未知错误}

新增一个失败的测试用例，在\ascii{runTest}抛出未知异常，模拟被测系统失败。

\begin{nodiff}{test/mars/core/TestCaseSpec.cc}
 \begin{c++}
namespace {
  struct NilException {};

  struct UnknownErrorOnRunningTest : TestCase {
    const char* expectMsg() const {
      return "uncaught unknown exception in the runTest\n";
    }

  private:
    void runTest() override {
      throw NilException();
    }
  };
}

TEST_F(TestCaseSpec, extract_unknown_error_msg_on_running_test_failed) {
  UnknownErrorOnRunningTest test;
  run(test);

  auto& errors = result.getErrors();
  ASSERT_EQ(1, errors.size());
  ASSERT_EQ(test.expectMsg(), errors.front());
}
 \end{c++}
\end{nodiff}

\subsubsection{缓存错误}

使用通配符捕获所有未知异常，并将异常信息添加至缓存。此时，因为不知道具体异常类型，异常详情置为空字符串。

\begin{nodiff}{src/mars/core/TestResult.cc}
 \begin{c++}
#include <mars/core/TestResult.h>

bool TestResult::protect(const TestCaseFunctor& f) {
  try {
    return f();
  } catch (const AssertionError& e) {
    addFailure(std::string("assertion fail") + ' ' + f.where() + '\n' + e.what());
  } catch (const std::exception& e) {
    addError(std::string("uncaught std::exception") + ' ' + f.where() + '\n' + e.what());
  } catch (...) {
    addError(std::string("uncaught unknown exception") + " " + f.where() + "\n" + "");
  }
  return false;
}

// ...
 \end{c++}
\end{nodiff}

至此，测试通过。

\subsubsection{计数器实现}

可以删除\ascii{numOfErrors, numOfFailure}的计数器，通过查询集合的\ascii{size}直接返回。当然，\ascii{TestResult}的默认构造函数也无用武之地了，一并删除之。

\begin{diff}{include/mars/core/TestResult.h}
 \begin{minicpp}
#include <string>
#include <vector>

struct TestCaseFunctor;

struct TestResult {
  int failCount() const;
  int errorCount() const;

  bool protect(const TestCaseFunctor&);

  using TestFailures = std::vector<std::string>;
  const TestFailures& getFailures() const;

  using TestErrors = std::vector<std::string>;
  const TestErrors& getErrors() const;

private:
  void addFailure(std::string&& msg);
  void addError(std::string&& msg);

private:
  TestFailures failures;
  TestErrors errors;
};
 \end{minicpp}
\tcblower
 \begin{minicpp}
#include <mars/core/TestResult.h>

int TestResult::failCount() const {
  return failures.size();
}

int TestResult::errorCount() const {
  return errors.size();
}

inline void TestResult::addFailure(std::string&& msg) {
  failures.emplace_back(std::move(msg));
}

inline void TestResult::addError(std::string&& msg) {
  errors.emplace_back(std::move(msg));
}

// ...
 \end{minicpp}
\end{diff}

\end{content}

\section{值对象}

\begin{content}

\subsection{测试用例}

使用字符串表示异常信息是一种脆弱的设计，可以将其重构为值对象，从而得到更稳定的设计。首先，重构既有的测试用例，使其失败。

\begin{nodiff}{test/mars/core/TestCaseSpec.cc}
 \begin{c++}
namespace {
  struct FailureOnRunningTest : TestCase {
    const char* expectMsg() const {
      return "assertion fail in the runTest\n"
             "product.cc:57\n"
             "expected value == 2, but got 3";
    }

  private:
    void runTest() override {
      throw AssertionError("product.cc:57", "expected value == 2, but got 3");
    }
  };
}

TEST_F(TestCaseSpec, extract_except_msg_on_running_test_failed) {
  FailureOnRunningTest test;
  run(test);

  auto& fails = result.getFailures();
  ASSERT_EQ(1, fails.size());

  auto& fail = fails[0];
  ASSERT_TRUE(fail.isFailure());
  ASSERT_EQ(test.expectMsg(), fail.getExceptionMsg());
}
 \end{c++}
\end{nodiff}

测试用例使用\ascii{auto}自动类型推演，没有显式给出具体的类型。但是，该值对象约定具有\ascii{isFailure， getExceptionMsg}的接口定义。

\subsection{定义值对象}

为了快速通过测试，定义值对象\ascii{TestFailure}，相对原生的\ascii{std::string}，它相对更加稳定和抽象，并更具有表达力。

\begin{leftbar}
 \begin{c++}[caption={\ttfamily{include/mars/except/TestFailure.h}}]
#include <string>

struct TestFailure {
  TestFailure(std::string&& msg, bool failure);

  bool isFailure() const;
  bool isError() const;
  const std::string& getExceptionMsg() const;

private:
  std::string msg;
  bool failure;
};
 \end{c++}
\end{leftbar}

其实现非常简单。

\begin{leftbar}
 \begin{c++}[caption={\ttfamily{src/mars/except/TestFailure.cc}}]
#include "mars/except/TestFailure.h"

TestFailure::TestFailure(std::string&& msg, bool failure)
  : msg(std::move(msg)), failure(failure) {
}

bool TestFailure::isError() const {
  return !failure;
}

bool TestFailure::isFailure() const {
  return failure;
}

const std::string& TestFailure::getExceptionMsg() const {
  return msg;
}
 \end{c++}
\end{leftbar}

\subsection{重构：断言失败}

将\code{failures}的元素类型\code{std::string}重构为\code{TestFailure}。

\begin{leftbar}
 \begin{c++}[caption={\ttfamily{include/mars/core/TestResult.h}}]
#include <vector>
#include <string>
#include "mars/except/TestFailure.h"

struct TestCaseFunctor;

struct TestResult {
  int failCount() const;
  int errorCount() const;

  const std::vector<TestFailure>& getFailures() const;
  const std::vector<std::string>& getErrors() const;

  bool protect(const TestCaseFunctor&);

private:
  void onFail(std::string&& msg);
  void onError(std::string&& msg);

private:
  std::vector<TestFailure> failures;
  std::vector<std::string> errors;
};
 \end{c++}
\end{leftbar}

在实现文件中，重构完成\ascii{TestFailure}的缓存。

\begin{leftbar}
 \begin{c++}[caption={\ttfamily{src/mars/core/TestResult.cc}}]
#include "mars/core/TestResult.h"
#include "mars/core/internal/TestCaseFunctor.h"
#include "mars/except/AssertionError.h"

// ...

const std::vector<TestFailure>& TestResult::getFailures() const {
  return failures;
}

const std::vector<std::string>& TestResult::getErrors() const {
  return errors;
}

bool TestResult::protect(const TestCaseFunctor& f) {
  try {
    return f();
  } catch (const AssertionError& e) {
    onFail(std::string("assertion fail") + " " + f.where() + "\n" + e.what());
  } catch (const std::exception& e) {
    onError(std::string("uncaught std::exception") + " " + f.where() + "\n" + e.what());
  } catch (...) {
    onError(std::string("uncaught unknown exception") + " " + f.where() + "\n" + "");
  }
  return false;
}

void TestResult::onFail(std::string&& msg) {
  failures.emplace_back(std::move(msg), true);
}

void TestResult::onError(std::string&& msg) {
  errors.emplace_back(std::move(msg));
}
 \end{c++}
\end{leftbar}

至此，测试通过。

\subsection{重构：错误}

依葫芦画瓢，添加测试用例，

将\code{errors}的元素类型\code{std::string}重构为\code{TestFailure}。

\begin{leftbar}
 \begin{c++}[caption={\ttfamily{include/mars/core/TestResult.h}}]
#include <vector>
#include <string>
#include "mars/except/TestFailure.h"

struct TestCaseFunctor;

struct TestResult {
  int failCount() const;
  int errorCount() const;

  const std::vector<TestFailure>& getFailures() const;
  const std::vector<TestFailure>& getErrors() const;

  bool protect(const TestCaseFunctor&);

private:
  void onFail(std::string&& msg);
  void onError(std::string&& msg);

private:
  std::vector<TestFailure> failures;
  std::vector<TestFailure> errors;
};
 \end{c++}
\end{leftbar}

在实现文件中，重构完成\ascii{TestFailure}的构造与缓存。

\begin{leftbar}
 \begin{c++}[caption={\ttfamily{src/mars/core/TestResult.cc}}]
#include "mars/core/TestResult.h"
#include "mars/core/internal/TestCaseFunctor.h"
#include "mars/except/AssertionError.h"

// ...

const std::vector<TestFailure>& TestResult::getFailures() const {
  return failures;
}

const std::vector<TestFailure>& TestResult::getErrors() const {
  return errors;
}

bool TestResult::protect(const TestCaseFunctor& f) {
  try {
    return f();
  } catch (const AssertionError& e) {
    onFail(std::string("assertion fail") + " " + f.where() + "\n" + e.what());
  } catch (const std::exception& e) {
    onError(std::string("uncaught std::exception") + " " + f.where() + "\n" + e.what());
  } catch (...) {
    onError(std::string("uncaught unknown exception") + " " + f.where() + "\n" + "");
  }
  return false;
}

void TestResult::onFail(std::string&& msg) {
  failures.emplace_back(std::move(msg), true);
}

void TestResult::onError(std::string&& msg) {
  errors.emplace_back(std::move(msg), false);
}
 \end{c++}
\end{leftbar}

至此，测试通过。

\subsection{实现统一}

在\ascii{TestResult}中便可以删除既有的\ascii{errors}列表，及其相关的查询接口\ascii{getErrors}；统一使用\ascii{failures}一个缓存列表，及其\ascii{getFailures}一个查询接口。至此，消除了失败与错误两种重复表示，统一了接口的使用方式。

\begin{leftbar}
 \begin{c++}[caption={\ttfamily{include/mars/core/TestResult.h}}]
#include <string>
#include <vector>
#include <mars/except/TestFailure.h>

struct TestCaseFunctor;

struct TestResult {
  int failCount() const;
  int errorCount() const;

  const std::vector<TestFailure>& getFailures() const;

  bool protect(const TestCaseFunctor&);

private:
  void onFail(std::string&& msg);
  void onError(std::string&& msg);

private:
  std::vector<TestFailure> failures;
};
 \end{c++}
\end{leftbar}

在实现文件中，替换所有\ascii{errors}为\ascii{failures}。

\begin{leftbar}
 \begin{c++}[caption={\ttfamily{src/mars/core/TestResult.cc}}]
#include "mars/core/TestResult.h"
#include "mars/core/internal/TestCaseFunctor.h"
#include "mars/except/AssertionError.h"
#include "mars/except/TestFailure.h"

// ...

const std::vector<TestFailure>& TestResult::getFailures() const {
  return failures;
}

bool TestResult::protect(const TestCaseFunctor& f) {
  try {
    return f();
  } catch (const AssertionError& e) {
    onFail(std::string("assertion fail") + ' ' + f.where() + '\n' + e.what());
  } catch (const std::exception& e) {
    onError(std::string("uncaught std::exception") + ' ' + f.where() + '\n' + e.what());
  } catch (...) {
    onError(std::string("uncaught unknown exception") + ' ' + f.where() + '\n' + "");
  }
  return false;
}

void TestResult::onFail(std::string&& msg) {
  failures.emplace_back(std::move(msg), true);
}

void TestResult::onError(std::string&& msg) {
  failures.emplace_back(std::move(msg), false);
}
 \end{c++}
\end{leftbar}

\subsubsection{计数器实现}

\begin{leftbar}
 \begin{c++}[caption={\ttfamily{src/mars/core/TestResult.cc}}]
#include "mars/core/TestResult.h"
#include "mars/except/TestFailure.h"

// ...

template <typename Pred>
inline int TestResult::count(Pred pred) const {
  return std::count_if(failures.begin(), failures.end(), pred);
}

int TestResult::failCount() const {
  return count([](auto& e) {
    return e.isFailure();
  });
}

int TestResult::errorCount() const {
  return count([](auto& e) {
    return e.isError();
  });
}
 \end{c++}
\end{leftbar}

\subsection{工厂方法}

创建异常信息的工厂方法\ascii{msg}，得到可复用的代码实现。

\begin{leftbar}
 \begin{c++}[caption={\ttfamily{src/mars/core/TestResult.cc}}]
namespace {
  std::string msg(const char* why, const char* where, const char* what) {
    return std::string(why) + ' ' + where + '\n' + what;
  }
}

bool TestResult::protect(const TestCaseFunctor& f) {
  try {
    return f();
  } catch (const AssertionError& e) {
    onFail(msg("assertion fail", f.where(), e.what()));
  } catch (const std::exception& e) {
    onError(msg("assertion fail", f.where(), e.what()));
  } catch (...) {
    onError(msg("assertion fail", f.where(), ""));
  }
  return false;
}

void TestResult::onFail(std::string&& msg) {
  failures.emplace_back(std::move(msg), true);
}

void TestResult::onError(std::string&& msg) {
  failures.emplace_back(std::move(msg), false);
}
 \end{c++}
\end{leftbar}

\subsection{实用宏}

\begin{leftbar}
 \begin{c++}[caption={\ttfamily{src/mars/core/TestResult.cc}}]
inline void TestResult::onFail(std::string&& msg) {
  failures.emplace_back(std::move(msg), true);
}

inline void TestResult::onError(std::string&& msg) {
  failures.emplace_back(std::move(msg), false);
}

namespace {
  struct NilException {
    const char* what() const {
      return "";
    }
  };

  inline std::string msg(const char* why, const char* where, const char* what) {
    return std::string(why) + ' ' + where + '\n' + what;
  }
}

#define ON_FAIL(except)  onFail(msg(except, f.where(), e.what()))
#define ON_ERROR(except) onError(msg(except, f.where(), e.what()))

bool TestResult::protect(const TestCaseFunctor& f) {
  try {
    return f();
  } catch (const AssertionError& e) {
    ON_FAIL("assertion fail");
  } catch (const std::exception& e) {
    ON_ERROR("uncaught std::exception");
  } catch (...) {
    NilException e;
    ON_ERROR("uncaught unknown exception");
  }
  return false;
}
 \end{c++}
\end{leftbar}

\end{content}